Workbook

Sheet DATA
A1: Non-Operation | B1: JobShop | C1: Work Date | D1: Shift Type | E1: Start Time | F1: End Time | G1: Time | H1: Detail | I1: Member Qty | J1: Man Hour | K1: Place | L1: Caused Dept | M1: Outsourcing Corp. | N1: Place | O1: Remark | P1: Create Date | Q1: Create By
A2: Lunch | B2: 550-I | C2: 45973 | D2: B | E2: 2025-11-12 20:45:00 | F2: 2025-11-12 21:00:00 | G2: 15 | I2: 0 | J2: 1 | K2: Inside Company | N2: 1 | P2: 2025-11-12 22:29:11 | Q2: JAYAKUMAR G
A3: Lunch | B3: 2300-I | C3: 45973 | D3: B | E3: 2025-11-12 20:00:00 | F3: 2025-11-12 20:30:00 | G3: 30 | I3: 0 | J3: 1 | K3: Inside Company | N3: 1 | O3: DINNER | P3: 2025-11-12 23:02:36 | Q3: PURUSOTHAMAN S
A4: Manpower shoratge | B4: 2300-I | C4: 45973 | D4: A | E4: 2025-11-12 07:00:00 | F4: 2025-11-12 07:20:00 | G4: 20 | I4: 0 | J4: 1 | K4: Inside Company | N4: 1 | P4: 2025-11-12 16:34:18 | Q4: MOHAN D
A5: Manpower shoratge | B5: 2500-I | C5: 45973 | D5: C | E5: 2025-11-13 00:00:00 | F5: 2025-11-13 00:15:00 | G5: 15 | I5: 0 | J5: 1 | K5: Inside Company | N5: 1 | P5: 2025-11-13 06:40:14 | Q5: SELVAKUMAR N
A6: Mold Change | B6: 220-I | C6: 45973 | D6: C | E6: 2025-11-13 00:00:00 | F6: 2025-11-13 00:15:00 | G6: 15 | I6: 0 | J6: 1 | K6: Inside Company | N6: 1 | O6: mould unloding | P6: 2025-11-13 07:10:24 | Q6: SANTHOSH KUMAR D
A7: Mold Change | B7: 220-I | C7: 45973 | D7: C | E7: 2025-11-13 04:45:00 | F7: 2025-11-13 05:00:00 | G7: 15 | I7: 0 | J7: 1 | K7: Inside Company | N7: 1 | O7: mould loding | P7: 2025-11-13 07:10:54 | Q7: SANTHOSH KUMAR D
A8: Mold Change | B8: 220-I | C8: 45973 | D8: B | E8: 2025-11-12 20:05:00 | F8: 2025-11-12 20:35:00 | G8: 30 | I8: 0 | J8: 1 | K8: Inside Company | N8: 1 | P8: 2025-11-12 22:23:15 | Q8: JAYAKUMAR G
A9: Mold Change | B9: 220-II | C9: 45973 | D9: A | E9: 2025-11-12 15:00:00 | F9: 2025-11-12 15:29:59 | G9: 30 | I9: 0 | J9: 1 | K9: Inside Company | N9: 1 | O9: mould change | P9: 2025-11-12 15:22:05 | Q9: YUVARAJ E
A10: Mold Change | B10: 450-I | C10: 45973 | D10: B | E10: 2025-11-12 22:45:00 | F10: 2025-11-12 23:15:00 | G10: 30 | I10: 0 | J10: 1 | K10: Inside Company | N10: 1 | P10: 2025-11-12 23:49:08 | Q10: JAYAKUMAR G
A11: Mold Change | B11: 550-III | C11: 45973 | D11: C | E11: 2025-11-13 01:00:00 | F11: 2025-11-13 01:30:00 | G11: 30 | I11: 0 | J11: 1 | K11: Inside Company | N11: 1 | P11: 2025-11-13 06:31:05 | Q11: SANTHOSH KUMAR D
A12: Mold Change | B12: 650-II | C12: 45973 | D12: A | E12: 2025-11-12 07:00:00 | F12: 2025-11-12 07:30:00 | G12: 30 | I12: 0 | J12: 1 | K12: Inside Company | N12: 1 | O12: mould change duct deforestern lhd | P12: 2025-11-12 11:44:43 | Q12: MOHAN D
A13: Mold Change | B13: 2000-I | C13: 45973 | D13: B | E13: 2025-11-12 21:20:00 | F13: 2025-11-12 22:00:00 | G13: 40 | I13: 0 | J13: 1 | K13: Inside Company | N13: 1 | O13: MOULD CHANGE | P13: 2025-11-12 23:03:22 | Q13: PURUSOTHAMAN S
A14: Mold Change | B14: 1800-II | C14: 45973 | D14: C | E14: 2025-11-13 02:10:00 | F14: 2025-11-13 02:30:07 | G14: 20 | I14: 0 | J14: 1 | K14: Inside Company | N14: 1 | O14: SU2I FL SIDE SILL N LINE MOULD UNLOAD | P14: 2025-11-13 06:49:41 | Q14: SELVAKUMAR N
A15: Mold Change | B15: 1800-II | C15: 45973 | D15: C | E15: 2025-11-13 02:55:00 | F15: 2025-11-13 03:15:00 | G15: 20 | I15: 0 | J15: 1 | K15: Inside Company | N15: 1 | O15: MOULD LOAD SU2I SIDE SILL OPT | P15: 2025-11-13 06:53:31 | Q15: SELVAKUMAR N
A16: Mold Change | B16: 1800-II | C16: 45973 | D16: B | E16: 2025-11-12 15:30:00 | F16: 2025-11-12 16:00:00 | G16: 30 | I16: 0 | J16: 1 | K16: Inside Company | N16: 1 | O16: mould loading | P16: 2025-11-13 00:04:37 | Q16: JAYAKUMAR G
A17: Mold Change | B17: 2300-I | C17: 45973 | D17: A | E17: 2025-11-12 12:40:00 | F17: 2025-11-12 13:40:00 | G17: 60 | I17: 0 | J17: 1 | K17: Inside Company | N17: 1 | P17: 2025-11-12 16:48:16 | Q17: MOHAN D
A18: Mold Change | B18: 2300-I | C18: 45973 | D18: C | E18: 2025-11-13 06:40:00 | F18: 2025-11-13 06:59:59 | G18: 20 | I18: 0 | J18: 1 | K18: Inside Company | N18: 1 | O18: MOLD LOADING | P18: 2025-11-13 06:58:04 | Q18: SELVAKUMAR N
A19: Mold Change | B19: 2300-I | C19: 45973 | D19: C | E19: 2025-11-13 02:35:00 | F19: 2025-11-13 02:55:00 | G19: 20 | I19: 0 | J19: 1 | K19: Inside Company | N19: 1 | O19: MOLD UNLOADING | P19: 2025-11-13 06:57:01 | Q19: SELVAKUMAR N
A20: Colour Change | B20: 220-I | C20: 45973 | D20: B | E20: 2025-11-12 20:35:00 | F20: 2025-11-12 20:55:00 | G20: 20 | I20: 0 | J20: 1 | K20: Inside Company | N20: 1 | P20: 2025-11-12 22:23:29 | Q20: JAYAKUMAR G
A21: Colour Change | B21: 220-II | C21: 45973 | D21: B | E21: 2025-11-12 15:30:00 | F21: 2025-11-12 16:00:00 | G21: 30 | I21: 0 | J21: 1 | K21: Inside Company | N21: 1 | P21: 2025-11-12 22:21:33 | Q21: JAYAKUMAR G
A22: Colour Change | B22: 550-I | C22: 45973 | D22: C | E22: 2025-11-13 03:25:00 | F22: 2025-11-13 03:45:00 | G22: 20 | I22: 0 | J22: 1 | K22: Inside Company | N22: 1 | P22: 2025-11-13 06:10:19 | Q22: SANTHOSH KUMAR D
A23: Colour Change | B23: 550-I | C23: 45973 | D23: A | E23: 2025-11-12 10:35:00 | F23: 2025-11-12 10:50:00 | G23: 15 | I23: 0 | J23: 1 | K23: Inside Company | N23: 1 | O23: ypk to mmh | P23: 2025-11-12 11:35:33 | Q23: MOHAN D
A24: Colour Change | B24: 550-II | C24: 45973 | D24: B | E24: 2025-11-12 20:45:00 | F24: 2025-11-12 21:45:00 | G24: 60 | I24: 0 | J24: 1 | K24: Inside Company | N24: 1 | P24: 2025-11-12 22:33:16 | Q24: JAYAKUMAR G
A25: Colour Change | B25: 1050-I | C25: 45973 | D25: B | E25: 2025-11-12 22:20:08 | F25: 2025-11-12 23:50:08 | G25: 90 | I25: 0 | J25: 1 | K25: Inside Company | N25: 1 | O25: NNB TO MMH CHANGE | P25: 2025-11-12 23:58:07 | Q25: PURUSOTHAMAN S
A26: Colour Change | B26: 1050-II | C26: 45973 | D26: A | E26: 2025-11-12 14:10:00 | F26: 2025-11-12 14:30:00 | G26: 20 | I26: 0 | J26: 1 | K26: Inside Company | N26: 1 | P26: 2025-11-12 15:15:12 | Q26: KALAIMATHI R
A27: Colour Change | B27: 1050-II | C27: 45973 | D27: C | E27: 2025-11-13 02:40:00 | F27: 2025-11-13 03:10:00 | G27: 30 | I27: 0 | J27: 1 | K27: Inside Company | N27: 1 | O27: YBK TO NNB | P27: 2025-11-13 06:02:58 | Q27: SELVAKUMAR N
A28: Colour Change | B28: 1800-I | C28: 45973 | D28: B | E28: 2025-11-12 20:40:00 | F28: 2025-11-12 21:20:00 | G28: 40 | I28: 0 | J28: 1 | K28: Inside Company | N28: 1 | O28: COLOUR CHANGE NNB TO YGN | P28: 2025-11-12 23:04:29 | Q28: PURUSOTHAMAN S
A29: Colour Change | B29: 2000-I | C29: 45973 | D29: B | E29: 2025-11-12 16:40:00 | F29: 2025-11-12 17:10:00 | G29: 30 | I29: 0 | J29: 1 | K29: Inside Company | N29: 1 | O29: YGN TO NNB | P29: 2025-11-13 01:30:27 | Q29: SELVAKUMAR N
A30: Colour Change | B30: 2000-I | C30: 45973 | D30: C | E30: 2025-11-13 02:20:04 | F30: 2025-11-13 03:10:04 | G30: 50 | I30: 0 | J30: 1 | K30: Inside Company | N30: 1 | O30: nnb to ygn | P30: 2025-11-13 06:23:01 | Q30: SELVAKUMAR N
A31: Colour Change | B31: 2300-I | C31: 45973 | D31: A | E31: 2025-11-12 13:40:00 | F31: 2025-11-12 14:20:00 | G31: 40 | I31: 0 | J31: 1 | K31: Inside Company | N31: 1 | O31: WDN TO BK | P31: 2025-11-12 16:49:09 | Q31: MOHAN D
A32: Colour Change | B32: 2500-I | C32: 45973 | D32: B | E32: 2025-11-12 18:00:00 | F32: 2025-11-12 18:45:00 | G32: 45 | I32: 0 | J32: 1 | K32: Inside Company | N32: 1 | O32: nnb to ygn colur change | P32: 2025-11-12 23:00:52 | Q32: PURUSOTHAMAN S
A33: Colour Change | B33: 2500-I | C33: 45973 | D33: A | E33: 2025-11-12 07:00:00 | F33: 2025-11-12 07:40:00 | G33: 40 | I33: 0 | J33: 1 | K33: Inside Company | N33: 1 | O33: ygn to nnb | P33: 2025-11-12 15:23:48 | Q33: YUVARAJ E
A34: Crane busy | B34: 2300-I | C34: 45973 | D34: A | E34: 2025-11-12 12:00:00 | F34: 2025-11-12 12:30:00 | G34: 30 | I34: 0 | J34: 1 | K34: Inside Company | N34: 1 | O34: RM STORE USING | P34: 2025-11-12 16:47:03 | Q34: MOHAN D
A35: Mould Breakdown | B35: 220-I | C35: 45973 | D35: B | E35: 2025-11-12 23:15:00 | F35: 2025-11-12 23:59:59 | G35: 45 | I35: 0 | J35: 1 | K35: Inside Company | N35: 1 | O35: running time cavity 2 magnet pin damage | P35: 2025-11-13 00:16:54 | Q35: JAYAKUMAR G
A36: Mould Breakdown | B36: 1050-I | C36: 45973 | D36: C | E36: 2025-11-13 04:00:00 | F36: 2025-11-13 04:40:00 | G36: 40 | I36: 0 | J36: 1 | K36: Inside Company | N36: 1 | O36: 3ND CORE SINGAL ISSUE | P36: 2025-11-13 06:06:52 | Q36: SELVAKUMAR N
A37: Mould Breakdown | B37: 1800-II | C37: 45973 | D37: C | E37: 2025-11-13 01:45:00 | F37: 2025-11-13 02:10:07 | G37: 25 | I37: 0 | J37: 1 | K37: Inside Company | N37: 1 | O37: EJECTION IFTER BACKWART ISSUE | P37: 2025-11-13 06:48:16 | Q37: SELVAKUMAR N
A38: Mould Breakdown | B38: 2300-I | C38: 45973 | D38: B | E38: 2025-11-12 17:20:00 | F38: 2025-11-12 17:45:00 | G38: 25 | I38: 0 | J38: 1 | K38: Inside Company | N38: 1 | O38: FLASH ISSUE | P38: 2025-11-12 23:02:14 | Q38: PURUSOTHAMAN S
... A52: EB Power cut | B52: 550-I | C52: 45973 | D52: A | E52: 2025-11-12 09:00:00 | F52: 2025-11-12 09:20:00 | G52: 20 | I52: 0 | J52: 1 | K52: Inside Company | N52: 1 | O52: power cut | P52: 2025-11-12 11:34:47 | Q52: MOHAN D
A53: EB Power cut | B53: 1050-II | C53: 45973 | D53: A | E53: 2025-11-12 09:00:00 | F53: 2025-11-12 09:15:00 | G53: 15 | I53: 0 | J53: 1 | K53: Inside Company | N53: 1 | P53: 2025-11-12 15:14:25 | Q53: KALAIMATHI R
...

Sheet MAN POWER SHORTAGE
A1: Non-Operation | B1: JobShop | C1: Work Date | D1: Shift Type | E1: Start Time | F1: End Time | G1: Time | H1: MC COST | I1: MANPOWER COST | J1: TOTAL COST
A2: Manpower shoratge | B2: 220-II | C2: 46064 | D2: B | E2: 2026-02-11 15:30:00 | F2: 2026-02-11 16:15:00 | G2: 45 | H2: =ROUND(VLOOKUP(B2,COST!$B$4:$I$24,8,0),1)*G2 -> 382.5 | I2: =(4.62*G2)*VLOOKUP(B2,COST!$B$4:$J$24,9,0) -> 207.9 | J2: =H2+I2 -> 590.4
A3: Manpower shoratge | B3: 550-I | C3: 46064 | D3: C | E3: 2026-02-12 00:00:00 | F3: 2026-02-12 00:30:00 | G3: 30 | H3: =ROUND(VLOOKUP(B3,COST!$B$4:$I$24,8,0),1)*G3 -> 396 | I3: =(4.62*G3)*VLOOKUP(B3,COST!$B$4:$J$24,9,0) -> 277.2 | J3: =H3+I3 -> 673.2
A4: Manpower shoratge | B4: 650-II | C4: 46064 | D4: C | E4: 2026-02-12 00:00:00 | F4: 2026-02-12 04:15:00 | G4: 255 | H4: =ROUND(VLOOKUP(B4,COST!$B$4:$I$24,8,0),1)*G4 -> 3442.5 | I4: =(4.62*G4)*VLOOKUP(B4,COST!$B$4:$J$24,9,0) -> 1178.1 | J4: =H4+I4 -> 4620.6
A5: Manpower shoratge | B5: 850-I | C5: 46064 | D5: C | E5: 2026-02-12 00:00:00 | F5: 2026-02-12 00:30:00 | G5: 30 | H5: =ROUND(VLOOKUP(B5,COST!$B$4:$I$24,8,0),1)*G5 -> 525 | I5: =(4.62*G5)*VLOOKUP(B5,COST!$B$4:$J$24,9,0) -> 138.6 | J5: =H5+I5 -> 663.6
A6: Manpower shoratge | B6: 1050-II | C6: 46064 | D6: C | E6: 2026-02-12 00:00:00 | F6: 2026-02-12 06:59:59 | G6: 420 | H6: =ROUND(VLOOKUP(B6,COST!$B$4:$I$24,8,0),1)*G6 -> 8190 | I6: =(4.62*G6)*VLOOKUP(B6,COST!$B$4:$J$24,9,0) -> 1940.4 | J6: =H6+I6 -> 10130.4
A7: Manpower shoratge | B7: 1800-I | C7: 46064 | D7: C | E7: 2026-02-12 00:00:00 | F7: 2026-02-12 00:30:00 | G7: 30 | H7: =ROUND(VLOOKUP(B7,COST!$B$4:$I$24,8,0),1)*G7 -> 789 | I7: =(4.62*G7)*VLOOKUP(B7,COST!$B$4:$J$24,9,0) -> 415.8 | J7: =H7+I7 -> 1204.8
A8: Manpower shoratge | B8: 1800-II | C8: 46064 | D8: C | E8: 2026-02-12 00:00:00 | F8: 2026-02-12 00:30:00 | G8: 30 | H8: =ROUND(VLOOKUP(B8,COST!$B$4:$I$24,8,0),1)*G8 -> 870 | I8: =(4.62*G8)*VLOOKUP(B8,COST!$B$4:$J$24,9,0) -> 693 | J8: =H8+I8 -> 1563
A9: Manpower shoratge | B9: 2300-I | C9: 46064 | D9: C | E9: 2026-02-12 00:00:00 | F9: 2026-02-12 01:00:00 | G9: 60 | H9: =ROUND(VLOOKUP(B9,COST!$B$4:$I$24,8,0),1)*G9 -> 2076 | I9: =(4.62*G9)*VLOOKUP(B9,COST!$B$4:$J$24,9,0) -> 831.6 | J9: =H9+I9 -> 2907.6
A10: Manpower shoratge | B10: 2500-I | C10: 46064 | D10: C | E10: 2026-02-12 00:00:00 | F10: 2026-02-12 06:59:59 | G10: 420 | H10: =ROUND(VLOOKUP(B10,COST!$B$4:$I$24,8,0),1)*G10 -> 12726 | I10: =(4.62*G10)*VLOOKUP(B10,COST!$B$4:$J$24,9,0) -> 5821.2 | J10: =H10+I10 -> 18547.2
G11: =SUM(G2:G10) -> 1320 | H11: =SUM(H2:H10) -> 29397 | I11: =SUM(I2:I10) -> 11503.8 | J11: =SUM(J2:J10) -> 40900.8

Sheet COST
A1: PRODUCTIONMANPOWER SHORTAGE DETAILS
A2: S.NO | B2: M/C ID | C2: DOWN TIME (Min) | F2: DOWN TIME (Cost) | I2: M/C COST(Per Min) | J2: MANPOWER
C3: A | D3: B | E3: C | F3: A | G3: B | H3: C
A4: 1 | B4: 220-I | I4: =507.25/60 -> 8.4541667 | J4: 2
A5: 2 | B5: 220-II | I5: =507.25/60 -> 8.4541667 | J5: 1
A6: 3 | B6: 350-I | E6: 30 | G6: =+E6*I6 -> 212.475 | I6: =424.95/60 -> 7.0825 | J6: 1
A7: 4 | B7: 450-I | E7: 30 | G7: =+I7*E7 -> 337.855 | I7: =675.71/60 -> 11.261833 | J7: 1
A8: 5 | B8: 550-I | I8: =789.72/60 -> 13.162 | J8: 2
A9: 6 | B9: 550-II | I9: =797.33/60 -> 13.288833 | J9: 1
A10: 7 | B10: 550-III | I10: =768.32/60 -> 12.805333 | J10: 1
A11: 8 | B11: 650-I | D11: 15 | E11: 15 | G11: =+D11*I11 -> 224.0425 | H11: =+E11*I11 -> 224.0425 | I11: =896.17/60 -> 14.936167 | J11: 1
A12: 9 | B12: 650-II | I12: =807.59/60 -> 13.459833 | J12: 1
A13: 10 | B13: 850-I | I13: =1049.5/60 -> 17.491667 | J13: 1
A14: 11 | B14: 850-II | D14: 30 | G14: =+D14*I14 -> 566.615 | I14: =1133.23/60 -> 18.887167 | J14: 1
A15: 12 | B15: 850-III | D15: 30 | G15: =+D15*I15 -> 559.55 | I15: =1119.1/60 -> 18.651667 | J15: 2
A16: 13 | B16: 850-IV | E16: 20 | H16: =+E16*I16 -> 385.70667 | I16: =1157.12/60 -> 19.285333 | J16: 0
A17: 14 | B17: 1050-I | I17: =1172.06/60 -> 19.534333 | J17: 1
A18: 15 | B18: 1050-II | E18: 20 | H18: =+E18*I18 -> 390.68667 | I18: =1172.06/60 -> 19.534333 | J18: 1
A19: 16 | B19: 1300-I | I19: =1555.62/60 -> 25.927 | J19: 3
A20: 17 | B20: 1800-I | I20: =1580.3/60 -> 26.338333 | J20: 3
A21: 18 | B21: 1800-II | I21: =1738.83/60 -> 28.9805 | J21: 5
A22: 19 | B22: 2000-I | I22: =1809.59/60 -> 30.159833 | J22: 3
A23: 20 | B23: 2300-I | I23: =2077.22/60 -> 34.620333 | J23: 3
A24: 21 | B24: 2500-I | I24: =1816.7/60 -> 30.278333 | J24: 3
A25: TOTAL | C25: - | D25: 75 | E25: 115 | F25: - | G25: 1901 | H25: 1000
C26: 190 | F26: 2901
